Traceback (most recent call last):
  File "c:\Users\coco\recoder\schedule_project\schedule_view.py", line 27, in run
    self.signals.done.emit(result)
    ~~~~~~~~~~~~~~~~~~~~~~^^^^^^^^
RuntimeError: Signal source has been deleted

During handling of the above exception, another exception occurred:

Traceback (most recent call last):
  File "c:\Users\coco\recoder\schedule_project\schedule_view.py", line 29, in run
    self.signals.done.emit({})
    ~~~~~~~~~~~~~~~~~~~~~~^^^^
RuntimeError: Signal source has been deleted
